Workbook

Sheet MASTER
A1: รูปภาพ | B1: รหัสสินค้า | C1: รูปแบบสินค้า | D1: ชื่อสินค้า | E1: สินค้าคงเหลือ | F1: Type | G1: Stock | H1: Min_Limit | I1: Note
A2: https://jst-yikan-picspace.oss-ap-southeast-1.aliyuncs.com/yikan/f49fa79052dc457caca04c526f9f2a9f.png | B2: SP001-สีชมพู | C2: SP001-สีชมพู | D2: ตู้เครื่องสำอาง | E2: 6 | F2: กลุ่ม ปกติ | H2: 0
A3: https://jst-yikan-picspace.oss-ap-southeast-1.aliyuncs.com/yikan/e572dba62dbb4b0b9bc579493ef9c0ca.jpg | B3: SP001-สีฟ้า | C3: SP001-สีฟ้า | D3: ตู้เครื่องสำอาง | E3: 40 | F3: กลุ่ม ปกติ | H3: 50
A4: https://jst-yikan-picspace.oss-ap-southeast-1.aliyuncs.com/yikan/f860e0c2c1a94d7e96c99b30ba029ac0.jpg | B4: SP002 | C4: SP002 | D4: เครื่องปั่นไฟฟ้า | E4: 12 | F4: กลุ่ม ปกติ | H4: 0
A5: https://jst-yikan-picspace.oss-ap-southeast-1.aliyuncs.com/yikan/8167fcb80ee948908844d72c001b77bb.jpg | B5: SP003 | C5: SP003 | D5: เหยือกน้ำญี่ปุ่น | E5: 58 | F5: กลุ่ม ปกติ | H5: 0
A6: https://jst-yikan-picspace.oss-ap-southeast-1.aliyuncs.com/yikan/c7d36c881e5844548a4a94d965c4c846.jpg | B6: SP004 | C6: SP004 | D6: ชุดหัวปั๊มสเเตนเลส | E6: 435 | F6: กลุ่ม ปกติ | H6: 0
A7: https://jst-yikan-picspace.oss-ap-southeast-1.aliyuncs.com/yikan/72ecc617fc27418685c7a91f07902e95.jpg | B7: SP005-30 ซม. | C7: SP005-30 ซม. | D7: ท่อต่อก็อกน้ำ | E7: 11 | F7: กลุ่ม ปกติ | H7: 0
A8: https://jst-yikan-picspace.oss-ap-southeast-1.aliyuncs.com/yikan/79405b05f7854c96915de8247bf4f907.jpg | B8: SP008 -สีดำ | C8: SP008 -สีดำ | D8: กระเป๋าสะพายข้าง | E8: 206 | F8: กลุ่ม ปกติ | H8: 0
A9: https://jst-yikan-picspace.oss-ap-southeast-1.aliyuncs.com/yikan/4b2b6ac8b15840b6a2899a9d66456a27.jpg | B9: SP008 -สีดำแถบทอง | C9: SP008 -สีดำแถบทอง | D9: กระเป๋าสะพายข้าง | E9: 456 | F9: กลุ่ม ปกติ | H9: 0
A10: https://jst-yikan-picspace.oss-ap-southeast-1.aliyuncs.com/yikan/281cfc249f6a4336bee6764201f76951.jpg | B10: SP008 -สีน้ำเงิน | C10: SP008 -สีน้ำเงิน | D10: กระเป๋าสะพายข้าง | E10: 143 | F10: กลุ่ม ปกติ | H10: 0
A11: https://jst-yikan-picspace.oss-ap-southeast-1.aliyuncs.com/yikan/d00688fd41a24ddbb1ec7c623e3436ec.jpg | B11: SP013 -สีเขียว | C11: SP013 -สีเขียว | D11: ที่วางช้อนส้อม | E11: 91 | F11: กลุ่ม ปกติ | H11: 0
A12: https://jst-yikan-picspace.oss-ap-southeast-1.aliyuncs.com/yikan/db90c580f95a4d02a1cbb457226ef383.jpg | B12: SP013 -สีเทา | C12: SP013 -สีเทา | D12: ที่วางช้อนส้อม | E12: 138 | F12: กลุ่ม ปกติ | H12: 0
A13: https://jst-yikan-picspace.oss-ap-southeast-1.aliyuncs.com/yikan/e2189ba2b4e5446babafdb09ff7cd8e2.jpg | B13: SP013 -สีขาว | C13: SP013 -สีขาว | D13: ที่วางช้อนส้อม | E13: 17 | F13: กลุ่ม ปกติ | H13: 0
... A635: https://jst-yikan-picspace.oss-ap-southeast-1.aliyuncs.com/yikan/3740d1651b7f4147823f41ad34705282.png | B635: SP589 | C635: SP589-1ชิ้น | D635: กระเป๋าใส่ผ้าเช็ดเเว่น Smash (SP589) | E635: -61 | F635: กลุ่ม SMASH | H635: 0
A636: https://jst-yikan-picspace.oss-ap-southeast-1.aliyuncs.com/yikan/aed86a9fba024c3fa0d1868a0c926617.png | B636: SP590-1ชิ้น | C636: SP590-1ชิ้น | D636: กล่องใส่ไหมขัดฟัน SP590-1ชิ้น | F636: กลุ่ม ปกติ | H636: 0
A637: https://jst-yikan-picspace.oss-ap-southeast-1.aliyuncs.com/yikan/b573a5d8323442aab3a52bc24d74584d.png | B637: SP591 | C637: SP591 | D637: สบู่ Y8 (SP591) | F637: กลุ่ม ปกติ | H637: 0
A638: https://jst-yikan-picspace.oss-ap-southeast-1.aliyuncs.com/yikan/28d9b20bdc1e44b099c98b360bae071d.png | B638: SP592 | C638: SP592 | D638: ครีม Y8 (SP592) | F638: กลุ่ม ปกติ | H638: 0
A639: https://jst-yikan-picspace.oss-ap-southeast-1.aliyuncs.com/yikan/68008b32675c475db6d71f78ca5e016b.png | B639: SP593 | C639: SP593 | D639: เซรั่ม Y8 (SP593) | F639: กลุ่ม ปกติ | H639: 0
A640: https://jst-yikan-picspace.oss-ap-southeast-1.aliyuncs.com/yikan/b09eafe9c8584931a627b121b2c401e9.png | B640: SP594 | C640: SP594 | D640: กันแดด Y8 (SP594) | F640: กลุ่ม ปกติ | H640: 0
A641: https://jst-yikan-picspace.oss-ap-southeast-1.aliyuncs.com/yikan/e6aad1b3c8d8423cbf34ca6940fd7097.png | B641: SP595-M | C641: SP595-M | D641: แผ่นรองฉี่หมา SP595 | F641: กลุ่ม ปกติ | H641: 0
A642: https://jst-yikan-picspace.oss-ap-southeast-1.aliyuncs.com/yikan/f797050c92a5471e99073c32b32fbcae.png | B642: SP595-XL | C642: SP595-XL | D642: แผ่นรองฉี่หมา SP595 | F642: กลุ่ม ปกติ | H642: 0
A643: https://jst-yikan-picspace.oss-ap-southeast-1.aliyuncs.com/yikan/32b483e5f9754261b143e54ae59d3851.png | B643: SP596-แดง | C643: SP596-แดง | D643: กิ๊บหนีบผม SP596 | F643: กลุ่ม ปกติ | H643: 0
A644: https://jst-yikan-picspace.oss-ap-southeast-1.aliyuncs.com/yikan/cb89a622bf344b91a4a5d3578abd59ff.png | B644: SP596-ขาว | C644: SP596-ขาว | D644: กิ๊บหนีบผม SP596 | F644: กลุ่ม ปกติ | H644: 0
A645: https://jst-yikan-picspace.oss-ap-southeast-1.aliyuncs.com/yikan/9c4a17c059ce45c9abe29decc62a4952.png | B645: SP596-ดำ | C645: SP596-ดำ | D645: กิ๊บหนีบผม SP596 | F645: กลุ่ม ปกติ | H645: 0
A646: https://jst-yikan-picspace.oss-ap-southeast-1.aliyuncs.com/yikan/0e00ea389bf541a382e56e35ff6481e0.png | B646: SP596-น้ำตาล | C646: SP596-น้ำตาล | D646: กิ๊บหนีบผม SP596 | F646: กลุ่ม ปกติ | H646: 0
A647: https://jst-yikan-picspace.oss-ap-southeast-1.aliyuncs.com/yikan/cb5d5b8f61154157a7aae2eed866035f.png | B647: SP597 | C647: SP597 | D647: อามิโน ลูทีน SP597 | F647: กลุ่ม อาหารเสริม | H647: 0
... A820: https://jst-yikan-picspace.oss-ap-southeast-1.aliyuncs.com/yikan/01ef043812e64bd9becf51efec47e47c.png | B820: SP545-6กล่อง | C820: SP545-6กล่อง | D820: ONE MORE (6กล่อง) SP545-6กล่อง | F820: กลุ่ม อาหารเสริม | H820: 0

Sheet LOGIN_LOG
A1: Timestamp | B1: Email
A2: 2026-01-05 13:01:58 | B2: stock@swiftpassion.net
A3: 2026-01-05 13:03:52 | B3: supanyastt@gmail.com
A4: 2026-01-05 19:13:29 | B4: moskerrycoco@gmail.com
A5: 2026-01-05 19:21:30 | B5: moskerrycoco@gmail.com
A6: 2026-01-05 19:30:50 | B6: moskerrycoco@gmail.com
A7: 2026-01-05 19:36:00 | B7: moskerrycoco@gmail.com
A8: 2026-01-05 19:46:58 | B8: moskerrycoco@gmail.com
A9: 2026-01-05 19:58:22 | B9: moskerrycoco@gmail.com
A10: 2026-01-06 04:59:34 | B10: moskerrycoco@gmail.com
A11: 2026-01-06 05:00:21 | B11: moskerrycoco@gmail.com
A12: 2026-01-06 05:00:45 | B12: moskerrycoco@gmail.com
... A165: 2026-01-24 13:30:21 | B165: supanyastt@gmail.com

Sheet PO_DATA
A1: รหัสสินค้า | B1: เลข PO | C1: ขนส่ง | D1: วันที่สั่งซื้อ | E1: วันที่ได้รับ | F1: ระยะเวลา | G1: จำนวน | H1: จำนวนที่ได้รับ | I1: ราคา/ชิ้น | J1: ราคา (หยวน) | K1: ราคา (บาท) | L1: เรทเงิน | M1: เรทค่าขนส่ง | N1: ขนาด (คิว) | O1: ค่าส่ง | P1: น้ำหนัก / KG | Q1: ราคา / ชิ้น (หยวน) | R1: SHOPEE | S1: LAZADA | T1: TIKTOK | U1: หมายเหตุ | V1: Link_Shop | W1: WeChat | X1: วันที่คาดว่าจะได้รับ
A2: SP358 | B2: YW0005475 | C2: ทางเรือ | D2: 2024-01-04 | E2: 2024-01-31 | F2: 27 | G2: 600 | H2: 600 | I2: 64.64 | J2: 6900 | K2: 34017 | L2: 4.93 | M2: 3100 | N2: 1.5368 | O2: 4764.08 | P2: 278.4 | Q2: 11.5 | R2: 159 | S2: 159 | T2: 179 | V2: https://shorturl.asia/zjPyg | X2: 2024-01-31
A3: SP358 | B3: YW0005475 | C3: ทางเรือ | D3: 2024-01-04 | E3: 2024-01-31 | F3: 27 | G3: 600 | H3: 600 | I3: 64.65 | J3: 6900 | K3: 38791 | L3: 4.93 | M3: 3100 | N3: 1.54 | O3: 4774 | P3: 278.4 | Q3: 11.5 | R3: 159 | S3: 159 | T3: 179 | V3: https://shorturl.asia/zjPyg | X3: 2024-01-31
A4: SP019 | B4: KEN0002543 | C4: ทางรถ | D4: 2024-01-04 | E4: 2024-01-07 | F4: 3 | G4: 10000 | H4: 10000 | I4: 14.4 | J4: 26480 | K4: 144013.2 | L4: 4.89 | M4: 5400 | N4: 2.69 | O4: 14526 | P4: 760 | Q4: 2.648 | R4: 69 | S4: 69 | T4: 69 | V4: https://shorturl.asia/7fvIm | W4: 13537969536 | X4: 2024-01-13
A5: SP019 | B5: KEN0002569 | C5: ทางรถ | D5: 2024-01-05 | E5: 2024-01-16 | F5: 11 | G5: 10000 | H5: 10000 | I5: 14.27 | J5: 26300 | K5: 128344 | L5: 4.88 | M5: 5400 | N5: 2.6627 | O5: 14378.58 | P5: 760 | Q5: 2.63 | R5: 69 | S5: 69 | T5: 69 | V5: https://shorturl.asia/7fvIm | W5: 13537969536 | X5: 2024-01-16
A6: SP079 | B6: KEN0002533-1 | C6: ทางรถ | D6: 2024-01-06 | E6: 2024-01-17 | F6: 11 | G6: 552 | H6: 552 | I6: 69 | J6: 6700 | K6: 33165 | L6: 4.95 | M6: 5400 | N6: 0.9114 | O6: 4921.56 | P6: 60 | Q6: 12.1377 | R6: 239 | S6: 239 | T6: 379 | X6: 2024-01-17
A7: SP108 | B7: KEN0002577 | C7: ทางรถ | D7: 2024-01-06 | E7: 2024-01-16 | F7: -722 | G7: 400 | H7: 400 | I7: 60.1 | J7: 4380 | K7: 21681 | L7: 4.95 | M7: 5400 | N7: 0.4371 | O7: 2360.34 | P7: 82 | Q7: 10.95 | R7: 159 | S7: 159 | T7: 169 | X7: 2024-01-16
A8: SP067 | B8: KEN0002532 | C8: ทางรถ | D8: 2024-01-06 | E8: 2024-01-17 | F8: 11 | G8: 408 | H8: 408 | I8: 128.18 | J8: 8300 | K8: 41085 | L8: 4.95 | M8: 5400 | N8: 2.0762 | O8: 11211.48 | P8: 394.91 | Q8: 20.3431 | R8: 290 | S8: 290 | T8: 290 | X8: 2024-01-17
A9: SP249 | B9: YW0005439 | C9: ทางเรือ | D9: 2024-01-06 | E9: 2024-01-31 | F9: 25 | G9: 50 | H9: 50 | I9: 4.55 | J9: 30 | K9: 148.5 | L9: 4.95 | M9: 3100 | N9: 0.0255 | O9: 79.05 | P9: 1.9 | Q9: 0.6 | R9: 29 | S9: 29 | T9: 39 | X9: 2024-01-31
A10: SP030 | B10: YW0004165 | C10: ทางเรือ | D10: 2024-01-09 | E10: 2024-01-30 | F10: 21 | G10: 300 | H10: 300 | I10: 86.98 | J10: 4270 | K10: 21221.9 | L10: 4.97 | M10: 3100 | N10: 1.5713 | O10: 4871.03 | P10: 357 | Q10: 14.2333 | R10: 259 | S10: 259 | T10: 99 | X10: 2024-01-30
A11: SP030 | B11: KEN0002540 | C11: ทางรถ | D11: 2024-01-09 | E11: 2024-01-16 | F11: 7 | G11: 20 | H11: 20 | I11: 93.54 | J11: 278 | K11: 1381.66 | L11: 4.97 | M11: 5400 | N11: 0.0906 | O11: 489.24 | P11: 25 | Q11: 13.9 | R11: 259 | S11: 259 | T11: 99 | X11: 2024-01-16
A12: SP066-สีดำ | B12: KEN0002530 | C12: ทางรถ | D12: 2024-01-09 | E12: 2024-01-16 | F12: 7 | G12: 294 | H12: 294 | I12: 1238.11 | J12: 6540 | K12: 359503.8 | L12: 54.97 | M12: 5400 | N12: 0.8335 | O12: 4500.9 | P12: 175 | Q12: 22.2449 | R12: 239 | S12: 239 | T12: 279 | X12: 2024-01-16
A13: SP019 | B13: KEN0002653-2 | C13: ทางรถ | D13: 2024-01-05 | E13: 2024-01-19 | F13: -564 | G13: 20000 | H13: 20000 | I13: 16.67 | J13: 61850 | K13: 308631.5 | L13: 4.99 | M13: 5400 | N13: 4.5757 | O13: 24708.78 | P13: 1210.4 | Q13: 3.0925 | R13: 0 | S13: 0 | T13: 0 | X13: 2024-06-22
A14: SP033 | B14: YW0005315 | C14: ทางเรือ | D14: 2024-01-10 | E14: 2024-02-13 | F14: 34 | G14: 800 | H14: 800 | I14: 154.73 | J14: 22000 | K14: 109560 | L14: 4.98 | M14: 3100 | N14: 4.5878 | O14: 14222.18 | P14: 1056 | Q14: 27.5 | R14: 350 | S14: 350 | T14: 420 | X14: 2024-02-13
A15: SP079 | B15: KEN0000978-2 | C15: ทางรถ | D15: 2024-01-10 | E15: 2024-01-25 | F15: 15 | G15: 552 | H15: 552 | I15: 66.27 | J15: 6680 | K15: 33266.4 | L15: 4.98 | M15: 5400 | N15: 0.6138 | O15: 3314.52 | P15: 40 | Q15: 12.1014 | R15: 239 | S15: 239 | T15: 139 | X15: 2024-01-25
A16: SP140 | B16: KEN0000068 | C16: ทางรถ | D16: 2024-02-16 | E16: 2024-03-03 | F16: 16 | G16: 192 | H16: 192 | I16: 88.19 | J16: 2600 | K16: 13000 | L16: 5 | M16: 5400 | N16: 0.7284 | O16: 3933.36 | P16: 103 | Q16: 13.5417 | R16: 0 | S16: 0 | T16: 0 | X16: 2024-03-01
A17: SPFREE015 | B17: YW0004190 | C17: ทางเรือ | D17: 2024-01-10 | E17: 2024-01-29 | F17: -731 | G17: 120 | H17: 120 | I17: 59.63 | J17: 1275 | K17: 7155.5 | L17: 4.98 | M17: 3100 | N17: 0.26 | O17: 806 | P17: 38.2 | Q17: 10.625 | R17: 0 | S17: 0 | T17: 0 | X17: 2024-01-29
... A19: SP051-สีดำ-6 มม. | B19: KEN0001063-1/KEN0001063-2 | C19: ทางเรือ | D19: 2024-01-11 | E19: 2024-04-04 | F19: 84 | G19: 10000 | H19: 10000 | I19: 5.41 | J19: 7660 | K19: 38223.4 | L19: 4.99 | M19: 3100 | N19: 5.1133 | O19: 15851.23 | P19: 404 | Q19: 0.766 | R19: 89 | S19: 89 | T19: 89 | X19: 2024-04-04
A20: SP157 | B20: KEN0000137 | C20: ทางเรือ | D20: 2024-02-16 | E20: 2024-03-08 | F20: 21 | G20: 1000 | H20: 1000 | I20: 37.62 | J20: 7020 | K20: 35451 | L20: 5.05 | M20: 3100 | N20: 0.701 | O20: 2173.1 | P20: 117 | Q20: 7.02 | R20: 99 | S20: 99 | T20: 99 | V20: https://shorturl.asia/nPSug | W20: 13928603642 | X20: 2024-03-08
A21: SP323 | B21: KEN0000869 | C21: ทางเรือ | D21: 2024-01-11 | E21: 2024-02-13 | F21: 33 | G21: 3000 | H21: 3000 | I21: 6.18 | J21: 3670 | K21: 18313.3 | L21: 4.99 | M21: 3100 | N21: 0.0766 | O21: 237.46 | P21: 54.99 | Q21: 1.2233 | R21: 29 | S21: 29 | T21: 49 | V21: https://shorturl.asia/7ykEb | W21: 18942406589 | X21: 2024-02-13
A22: SP019 | B22: KEN0002672 | C22: ทางรถ | D22: 2024-02-19 | E22: 2024-03-07 | F22: 17 | G22: 30000 | H22: 30000 | I22: 17 | J22: 91450 | K22: 455421 | L22: 4.98 | M22: 5400 | N22: 10.08 | O22: 54432 | P22: 2700 | Q22: 3.0483 | R22: 69 | S22: 69 | T22: 69 | V22: https://shorturl.asia/7fvIm | W22: 13537969536 | X22: 2024-03-07
A23: SP030 | B23: YW0005164 | C23: ทางเรือ | D23: 2024-02-19 | E23: 2024-01-19 | F23: -31 | G23: 300 | H23: 300 | I23: 71.17 | J23: 4270 | K23: 21350 | L23: 5 | M23: 0 | N23: 1.6868 | O23: 0 | P23: 370 | Q23: 14.2333 | R23: 139 | S23: 139 | T23: 139 | X23: 2024-03-19
A24: SP019 | B24: KEN0000031 | C24: ทางรถ | D24: 2024-01-17 | E24: 2024-01-25 | F24: 8 | G24: 10000 | H24: 10000 | I24: 14.4 | J24: 26200 | K24: 129690 | L24: 4.95 | M24: 5400 | N24: 2.6527 | O24: 14324.58 | P24: 775 | Q24: 2.62 | R24: 49 | S24: 49 | T24: 49 | V24: https://shorturl.asia/7fvIm | W24: 13537969536 | X24: 2024-01-25
A25: SP019 | B25: KEN0001059-1 | C25: ทางรถ | D25: 2024-01-22 | E25: 2024-01-31 | F25: 9 | G25: 10000 | H25: 10000 | I25: 16.73 | J25: 31800 | K25: 158046 | L25: 4.97 | M25: 5400 | N25: 1.7139 | O25: 9255.06 | P25: 445 | Q25: 3.18 | R25: 49 | S25: 49 | T25: 49 | V25: https://shorturl.asia/7fvIm | W25: 13537969536 | X25: 2024-01-31
A26: SP019 | B26: KEN0002677 | C26: ทางเรือ | D26: 2024-02-27 | E26: 2024-04-04 | F26: 37 | G26: 20000 | H26: 20000 | I26: 16.2 | J26: 60800 | K26: 323926 | L26: 4.98 | M26: 3100 | N26: 6.82 | O26: 21142 | P26: 1780 | Q26: 3.04 | R26: 69 | S26: 69 | T26: 69 | V26: https://shorturl.asia/7fvIm | W26: 13537969536 | X26: 2024-04-04
A27: SP019 | B27: KEN0001059-1 | C27: ทางรถ | D27: 2024-01-22 | E27: 2024-01-31 | F27: 9 | G27: 50 | H27: 50 | I27: 194.05 | J27: 90 | K27: 447.3 | L27: 4.97 | M27: 5400 | N27: 1.7139 | O27: 9255.06 | P27: 445 | Q27: 1.8 | R27: 49 | S27: 49 | T27: 49 | U27: 13537969536 | V27: https://shorturl.asia/7fvIm | X27: 2024-01-31
A28: SP248 | B28: YW0005736 | C28: ทางเรือ | D28: 2024-01-23 | E28: 2024-03-05 | F28: 42 | G28: 300 | H28: 300 | I28: 2.24 | J28: 110 | K28: 554.4 | L28: 5.04 | M28: 3100 | N28: 0.0382 | O28: 118.42 | P28: 1 | Q28: 0.3667 | R28: 45 | S28: 45 | T28: 59 | V28: https://shorturl.asia/Q8Huw | W28: 15819190011 | X28: 2024-03-05
A29: SP285-ไฟสีขาว | B29: KEN0001694 | C29: ทางเรือ | D29: 2024-01-23 | E29: 2024-02-26 | F29: 34 | G29: 1200 | H29: 1200 | I29: 23.56 | J29: 5390 | K29: 27165.6 | L29: 5.04 | M29: 3100 | N29: 0.3577 | O29: 1108.87 | P29: 135 | Q29: 4.4917 | R29: 69 | S29: 69 | T29: 69 | V29: https://shorturl.asia/kyX2U | X29: 2024-02-26
A30: SP045 | B30: YW0005740 | C30: ทางเรือ | D30: 2024-01-23 | E30: 2024-03-06 | F30: 43 | G30: 300 | H30: 300 | I30: 230.89 | J30: 8500 | K30: 42840 | L30: 5.04 | M30: 3100 | N30: 8.5248 | O30: 26426.88 | P30: 480 | Q30: 28.3333 | R30: 490 | S30: 490 | T30: 490 | V30: https://shorturl.asia/qJrOU | W30: 15068952767 | X30: 2024-03-06
A31: SP045 | B31: KEN0000062 | C31: ทางรถ | D31: 2024-01-23 | E31: 2024-02-06 | F31: 14 | G31: 100 | H31: 100 | I31: 299.6 | J31: 3150 | K31: 15876 | L31: 5.04 | M31: 5400 | N31: 2.6082 | O31: 14084.28 | P31: 180 | Q31: 31.5 | R31: 490 | S31: 490 | T31: 490 | V31: https://shorturl.asia/qJrOU | W31: 15068952767 | X31: 2024-02-06
A32: SP210 | B32: YW0001118 | C32: ทางเรือ | D32: 2024-02-22 | E32: 2024-03-12 | F32: 19 | G32: 200 | H32: 200 | I32: 62.21 | J32: 2300 | K32: 11638 | L32: 5.06 | M32: 3100 | N32: 0.2594 | O32: 804.14 | P32: 44 | Q32: 11.5 | R32: 99 | S32: 99 | T32: 129 | V32: https://shorturl.asia/KUvEZ | W32: 13819987030 | X32: 2024-03-12
A33: SP252 | B33: YW0005710 | C33: ทางเรือ | D33: 2024-01-24 | E33: 2024-02-21 | F33: 28 | G33: 200 | H33: 200 | I33: 25 | J33: 990 | K33: 4999.5 | L33: 5.05 | M33: 0 | N33: 0.3294 | O33: 0 | P33: 48.8 | Q33: 4.95 | R33: 89 | S33: 89 | T33: 99 | V33: https://shorturl.asia/oFB5Q | W33: 18367980456 | X33: 2024-02-21
A34: SP152 | B34: YW0005694 | C34: ทางเรือ | D34: 2024-01-26 | E34: 2024-02-21 | F34: 26 | G34: 2 | H34: 2 | I34: 620.5 | J34: 224 | K34: 1133.44 | L34: 5.06 | M34: 3100 | N34: 0.0347 | O34: 107.57 | P34: 6.9 | Q34: 112 | R34: 0 | S34: 0 | T34: 0 | X34: 2024-02-21
A35: SP192-สีเทา | B35: YW0005170 | C35: ทางเรือ | D35: 2024-02-23 | E35: 2024-03-22 | F35: 28 | G35: 1500 | H35: 1500 | I35: 10.47 | J35: 2680 | K35: 13560.8 | L35: 5.06 | M35: 3100 | N35: 0.6912 | O35: 2142.72 | P35: 65 | Q35: 1.7867 | R35: 69 | S35: 69 | T35: 69 | V35: https://shorturl.asia/f1JZh | W35: 17531957777 | X35: 2024-03-22
A36: SP045 | B36: YW0005149 | C36: ทางเรือ | D36: 2024-01-26 | E36: 2024-03-20 | F36: 54 | G36: 300 | H36: 300 | I36: 220.87 | J36: 8480 | K36: 42908.8 | L36: 5.06 | M36: 3100 | N36: 7.533 | O36: 23352.3 | P36: 480 | Q36: 28.2667 | R36: 490 | S36: 490 | T36: 490 | V36: https://shorturl.asia/qJrOU | W36: 15068952767 | X36: 2024-03-20
A37: SP045 | B37: KEN0002622-1 | C37: ทางรถ | D37: 2024-01-26 | E37: 2024-03-02 | F37: 36 | G37: 100 | H37: 100 | I37: 222.97 | J37: 3150 | K37: 15939 | L37: 5.06 | M37: 5400 | N37: 1.1774 | O37: 6357.96 | P37: 72 | Q37: 31.5 | R37: 490 | S37: 490 | T37: 490 | V37: https://shorturl.asia/qJrOU | W37: 15068952767 | X37: 2024-03-02
A38: SP152 | B38: K0001819 | C38: ทางรถ | D38: 2024-02-27 | E38: 2024-03-12 | F38: 14 | G38: 50 | H38: 50 | I38: 659.43 | J38: 5450 | K38: 27522.5 | L38: 5.05 | M38: 5400 | N38: 1.0091 | O38: 5449.14 | P38: 44 | Q38: 109 | R38: 1150 | S38: 1150 | T38: 1150 | V38: https://shorturl.asia/sB72c | W38: 13362931587 | X38: 2024-03-12
A39: SP019 | B39: KEN0000116 | C39: ทางรถ | D39: 2024-01-31 | E39: 2024-01-31 | F39: 710 | G39: 10000 | H39: 10000 | I39: 17.46 | J39: 31500 | K39: 174591 | L39: 4.97 | M39: 5400 | N39: 3.34 | O39: 18036 | P39: 925 | Q39: 3.15 | R39: 69 | S39: 69 | T39: 69 | V39: https://shorturl.asia/7fvIm | W39: 13537969536 | X39: 2024-02-16
A40: SP252 | B40: YW0005135 | C40: ทางเรือ | D40: 2024-02-29 | E40: 2024-03-26 | F40: 26 | G40: 200 | H40: 200 | I40: 28.69 | J40: 950 | K40: 4750 | L40: 5 | M40: 3100 | N40: 0.3186 | O40: 987.66 | P40: 49 | Q40: 4.75 | R40: 99 | S40: 99 | T40: 99 | V40: https://shorturl.asia/oFB5Q | W40: 18367980456 | X40: 2024-03-26
A41: SP045 | B41: YW0002491 | C41: ทางรถ | D41: 2024-05-02 | E41: 2024-05-28 | F41: 26 | G41: 300 | H41: 300 | I41: 229.13 | J41: 8475 | K41: 43561.5 | L41: 5.14 | M41: 3100 | N41: 8.1216 | O41: 25176.96 | P41: 480 | Q41: 28.25 | R41: 390 | S41: 390 | T41: 390 | V41: https://shorturl.asia/qJrOU | W41: 15068952767 | X41: 2024-05-28
...

Sheet Status
A1: ห้ามแก้ไข
A2: รหัสสินค้า | B2: ชื่อสินค้า | C2: 🔴 หมดเกลี้ยง | D2: ⚠️ ใกล้หมด | E2: 🟢 มีของ
A3: SPFREE569 | B3: (ของเเถม) ONE MORE (แบบ 1 แคปซูล)
A4: SPFREE225 | B4: (ของเเถม) เทสเตอร์อี้ฉี้ฯ
A5: SPFREE224 | B5: (ของเเถม) เทสเตอร์จิ่วเจิ้ง
A6: SPFREE028 | B6: (ของเเถม) พัดลม-สีดำ
A7: SPFREE027 | B7: (ของเเถม) กระปุกยาอันเล็กขาว
A8: SPFREE026 | B8: (ของเเถม) คูปองจิ่วเจิ้ง
A9: SPFREE025 | B9: (ของเเถม) นาฬิกา
A10: SPFREE024 | B10: (ของเเถม) ที่วัดออกซิเจนปลายนิ้ว
A11: SPFREE023 | B11: (ของเเถม) ที่ตรวจโควิด
A12: SPFREE022 | B12: (ของเเถม) เจลล้างมือ
A13: SPFREE021 | B13: (ของเเถม) กระบอกเก็บน้ำร้อน
A14: SPFREE020 | B14: (ของเเถม) ไม้ตียุง
... A105: SP584-1กล่อง | B105: Dr.Jel Dual Softgel SP584-1กล่อง
A106: SP584
A107: SP583 | B107: Dr.Jel TF (SP583)
A108: SP582 | B108: เทปใสป้องกันรอย SP582
A109: SP581-สีเทา | B109: ตัวล็อคประตู SP581
A110: SP581-สีเขียว | B110: ตัวล็อคประตู SP581
A111: SP580-สีชมพู | B111: ตะกร้าล้างผัก-ผลไม้ SP580
A112: SP579-สีเหลือง | B112: พัดลมเเอร์ SP579
A113: SP578-1ชิ้น | B113: แม่เหล็กติดประตู SP578-1ชิ้น
A114: SP577-สีฟ้า | B114: ถาดซ่อมมือถือ SP577
A115: SP577-สีเทา | B115: ถาดซ่อมมือถือ SP577
A116: SP576-M | B116: เบาะนอนสัตว์เลี้ยง
A117: SP576-L | B117: เบาะนอนสัตว์เลี้ยง
A118: SP575-สีฟ้า | B118: สายพยุงจูงเด็ก SP575
... A215: SP509-สีเทา | B215: แผ่นรองสัตว์เลี้ยงในรถ แบบฝั่งเดียว SP509
A216: SP509
A217: SP507-1ชิ้น
A218: SP507 | B218: หวี DKUB (สีชมพูม่วง)
A219: SP506-สีส้ม | B219: ไฟโซล่าเซลล์ปักในสวน (พลาสติก)
A220: SP506-สีขาว | B220: ไฟโซล่าเซลล์ปักในสวน (พลาสติก)
A221: SP505-สีส้ม | B221: ไฟโซล่าเซลล์ปักในสวน (สเเตนเลส)
A222: SP505-สีขาว | B222: ไฟโซล่าเซลล์ปักในสวน (สเเตนเลส)
A223: SP503 | B223: JIL S จิลเอส
A224: SP502 | B224: ตะไบขัดส้นเท้าสีส้ม SP502
A225: SP501 | B225: Philosoft Moist 24 Cream
A226: SP499 | B226: ที่เปิดฝากระป๋อง
...
